<?xml version="1.0" encoding="utf-8"?>
<robot name="pi_robot">

	<!-- * * * Link Definitions * * * -->
	
 	<link name="base_link">
		<visual>
		    <origin xyz="0 0 0" rpy="1.57 0 0"/>
			<geometry>
                <cylinder radius="0.01" length="0.05"/>
            </geometry>
			<material name="Cyan1">
	       		<color rgba="0 0.9 0.9 1.0"/>
	     	</material>
		</visual>	
	</link>

    <link name="2_link">
        <visual name="">
            <origin xyz="0.0 0.0 0.0" rpy="0.0 1.57 0.0"/>
            <geometry>
                <cylinder radius="0.01" length="0.1"/>
            </geometry>
            <material name="">
                <color rgba="1.0 0.0 0.0 1.0"/>
                <texture filename=""/>
            </material>
        </visual>
    </link>

    <link name="3_link">
        <visual name="">
            <origin xyz="0.0 0.0 0.0" rpy="0.0 1.57 0.0"/>
            <geometry>
                <cylinder radius="0.01" length="0.1"/>
            </geometry>
            <material name="">
                <color rgba="0.0 1.0 0.0 1.0"/>
                <texture filename=""/>
            </material>
        </visual>
    </link>

    <link name="4_link">
        <visual name="">
            <origin xyz="0.0 0.0 0.0" rpy="0.0 1.57 0.0"/>
            <geometry>
                <cylinder radius="0.01" length="0.1"/>
            </geometry>
            <material name="">
                <color rgba="0.0 1.0 0.0 1.0"/>
                <texture filename=""/>
            </material>
        </visual>
    </link>

    <link name="5_link">
        <visual name="">
            <origin xyz="0.0 0.0 0.0" rpy="0.0 1.57 0.0"/>
            <geometry>
                <cylinder radius="0.01" length="0.1"/>
            </geometry>
            <material name="">
                <color rgba="0.0 1.0 0.0 1.0"/>
                <texture filename=""/>
            </material>
        </visual>
    </link>

    <link name="6_link">
        <visual name="">
            <origin xyz="0.0 0.0 0.0" rpy="0.0 0.0 0.0"/>
            <geometry>
                <box size="0.1 0.1 0.02"/>
            </geometry>
            <material name="">
                <color rgba="0.0 0.9 0.9 1.0"/>
                <texture filename=""/>
            </material>
        </visual>
    </link>

    <joint name="1_joint" type="revolute">
        <origin xyz="0.0 0.0 0.0" rpy="0.0 0.0 0.0"/>
        <parent link="base_link"/>
        <child link="2_link"/>
        <axis xyz="0.0 1.0 0.0"/>
    </joint>

    <joint name="2_joint" type="revolute">
        <origin xyz="0.0 0.0 0.0" rpy="0.0 0.0 0.0"/>
        <parent link="2_link"/>
        <child link="3_link"/>
        <axis xyz="1.0 0.0 0.0"/>
    </joint>

    <joint name="3_joint" type="revolute">
        <origin xyz="0.0 0.0 0.042" rpy="0.0 0.0 0.0"/>
        <parent link="3_link"/>
        <child link="4_link"/>
        <axis xyz="1.0 0.0 0.0"/>
    </joint>

    <joint name="4_joint" type="revolute">
        <origin xyz="0.0 0.0 0.044" rpy="0.0 0.0 0.0"/>
        <parent link="4_link"/>
        <child link="5_link"/>
        <axis xyz="1.0 0.0 0.0"/>
    </joint>

    <joint name="5_joint" type="revolute">
        <origin xyz="0.0 0.0 0.045" rpy="0.0 0.0 0.0"/>
        <parent link="5_link"/>
        <child link="6_link"/>
        <axis xyz="0.0 0.0 1.0"/>
    </joint>
 
</robot>